Workbook

Sheet contadores
A1: IMPRESORA | B1: TIPO | C1: UBICACIÓN | D1: S/N | E1: TTL COPIAS / IMPRESIONES | F1: CONTADOR MAYO | G1: CONTADOR JUNIO | H1: TTL JUNIO | I1: CONTADOR JULIO | J1: TTL JULIO | K1: CONTADOR AGOSTO | L1: TTL AGOSTO | M1: CONTADOR SEPTIEMBRE | N1: TTL SEPTIEMBRE | O1: CONTADOR OCTUBRE | P1: TTL OCTUBRE | Q1: CONTADOR NOVIEMBRE | R1: TTL NOVIEMBRE | S1: CONTADOR DICIEMBRE | T1: TTL DICIEMBRE
A2: Ricoh MP | B2: B/N | C2: Piso 1 - OPERACIONES | D2: 00227 | E2: 5000 | F2: 102427 | G2: 110639 | H2: =IF(G2="","",G2-F2) -> 8212 | I2: 116524 | J2: =IF(I2="","",I2-G2) -> 5885 | K2: 121905 | L2: =IF(K2="","",K2-I2) -> 5381 | N2: =IF(M2="","",M2-K2) | P2: =IF(O2="","",O2-M2) | R2: =IF(Q2="","",Q2-O2) | T2: =IF(S2="","",S2-Q2)
A3: Kyocera M3655 | B3: B/N | C3: Piso 1 - PSICOLOGIA | D3: 08082 | E3: 5000 | F3: 202373 | G3: 210918 | H3: =IF(G3="","",G3-F3) -> 8545 | I3: 216813 | J3: =IF(I3="","",I3-G3) -> 5895 | K3: 222560 | L3: =IF(K3="","",K3-I3) -> 5747 | N3: =IF(M3="","",M3-K3) | P3: =IF(O3="","",O3-M3) | R3: =IF(Q3="","",Q3-O3) | T3: =IF(S3="","",S3-Q3)
A4: Ricoh MP 5054 | B4: B/N | C4: Piso 2 - CONT | D4: 00084 | E4: 5000 | F4: 219803 | G4: 224420 | H4: =IF(G4="","",G4-F4) -> 4617 | I4: 230443 | J4: =IF(I4="","",I4-G4) -> 6023 | K4: 235100 | L4: =IF(K4="","",K4-I4) -> 4657 | N4: =IF(M4="","",M4-K4) | P4: =IF(O4="","",O4-M4) | R4: =IF(Q4="","",Q4-O4) | T4: =IF(S4="","",S4-Q4)
A5: Ricoh MPC 4504 | B5: B/N | C5: Piso 2 - PROYECTOS | D5: 10089 | E5: 5000 | F5: 124046 | G5: 125720 | H5: =IF(G5="","",G5-F5) -> 1674 | I5: 127617 | J5: =IF(I5="","",I5-G5) -> 1897 | K5: 127944 | L5: =IF(K5="","",K5-I5) -> 327 | N5: =IF(M5="","",M5-K5) | P5: =IF(O5="","",O5-M5) | R5: =IF(Q5="","",Q5-O5) | T5: =IF(S5="","",S5-Q5)
A6: Ricoh MPC 4504 | B6: Color | C6: Piso 2 - PROYECTOS | D6: C-10089 | F6: 137444 | G6: 138001 | H6: =IF(G6="","",G6-F6) -> 557 | I6: 138202 | J6: =IF(I6="","",I6-G6) -> 201 | K6: 151648 | L6: =IF(K6="","",K6-I6) -> 13446 | N6: =IF(M6="","",M6-K6) | P6: =IF(O6="","",O6-M6) | R6: =IF(Q6="","",Q6-O6) | T6: =IF(S6="","",S6-Q6)
A7: Ricoh MPC 4504 | B7: B/N | C7: Piso 3 - PROMOTORES | D7: 60686 | E7: 5000 | F7: 606081 | G7: 611461 | H7: =IF(G7="","",G7-F7) -> 5380 | I7: 623044 | J7: =IF(I7="","",I7-G7) -> 11583 | K7: 630339 | L7: =IF(K7="","",K7-I7) -> 7295 | N7: =IF(M7="","",M7-K7) | P7: =IF(O7="","",O7-M7) | R7: =IF(Q7="","",Q7-O7) | T7: =IF(S7="","",S7-Q7)
A8: Ricoh MPC 4504 | B8: Color | C8: Piso 3 - PROMOTORES | D8: C-60686 | F8: 56862 | G8: 57340 | H8: =IF(G8="","",G8-F8) -> 478 | I8: 61760 | J8: =IF(I8="","",I8-G8) -> 4420 | K8: 63962 | L8: =IF(K8="","",K8-I8) -> 2202 | N8: =IF(M8="","",M8-K8) | P8: =IF(O8="","",O8-M8) | R8: =IF(Q8="","",Q8-O8) | T8: =IF(S8="","",S8-Q8)
A9: Ricoh MP 4504 | B9: B/N | C9: Piso 4 - COM | D9: 60310 | E9: 5000 | F9: 203700 | G9: 203808 | H9: =IF(G9="","",G9-F9) -> 108 | I9: 205215 | J9: =IF(I9="","",I9-G9) -> 1407 | K9: 205389 | L9: =IF(K9="","",K9-I9) -> 174 | N9: =IF(M9="","",M9-K9) | P9: =IF(O9="","",O9-M9) | R9: =IF(Q9="","",Q9-O9) | T9: =IF(S9="","",S9-Q9)
A10: Ricoh MP 4504 | B10: Color | C10: Piso 4 - COM | D10: C-60310 | F10: 346292 | G10: 346494 | H10: =IF(G10="","",G10-F10) -> 202 | I10: 348411 | J10: =IF(I10="","",I10-G10) -> 1917 | K10: 356482 | L10: =IF(K10="","",K10-I10) -> 8071 | N10: =IF(M10="","",M10-K10) | P10: =IF(O10="","",O10-M10) | R10: =IF(Q10="","",Q10-O10) | T10: =IF(S10="","",S10-Q10)

Sheet cont_usuario
A1: IMPRESORA | B1: USUARIO | C1: NOMBRE | D1: JUN / BN | E1: JUN COLOR | F1: JUL / BN | G1: JUL COLOR | H1: AGO / BN | I1: AGO COLOR | J1: SEP / BN | K1: SEP COLOR | L1: OCT / BN | M1: OCT COLOR | N1: NOV / BN | O1: NOV / COLOR | P1: DIC / BN | Q1: DIC / COLOR
A2: 60310 | B2: 0627 | C2: ISABELA ALDANA | D2: 0 | E2: 0 | F2: 0 | G2: 0 | H2: 0 | I2: 0
A3: 60310 | B3: 1312 | C3: NATALIA RENGIFO | D3: 0 | E3: 0 | F3: 0 | G3: 0 | H3: 0 | I3: 0
A4: 60310 | B4: 1982 | C4: LUCIA JARAMILLO | D4: 0 | E4: 8 | F4: 74 | G4: 231 | H4: 0 | I4: 4
A5: 60310 | B5: 2023 | C5: NATALIA RAMIREZ | D5: 13 | E5: 125 | F5: 55 | G5: 595 | H5: 0 | I5: 183
A6: 60310 | B6: 2024 | C6: CAMILA LOPEZ | D6: 47 | E6: 41 | F6: 1079 | G6: 937 | H6: 157 | I6: 7755
A7: 60310 | B7: 2026 | C7: DIANA OROZCO | D7: 7 | E7: 0 | F7: 0 | G7: 0 | H7: 0 | I7: 0
A8: 60310 | B8: 3232 | C8: MARIA PAULA | D8: 17 | E8: 1 | F8: 12 | G8: 4 | H8: 8 | I8: 6
A9: 60310 | B9: 3918 | C9: CATALINA LASSO | D9: 16 | E9: 0 | F9: 15 | G9: 0 | H9: 0 | I9: 0
A10: 60310 | B10: 4040 | C10: JUAN CARLOS OCAMPO | D10: 6 | E10: 27 | F10: 10 | G10: 307 | H10: 6 | I10: 122
A11: 60310 | B11: 4141 | C11: VALENTINA MOLANO | D11: 0 | E11: 0 | F11: 3 | G11: 0 | H11: 1 | I11: 1
A12: 00227 | B12: 0711 | C12: RICARDO PACHON | D12: 249 | E12: 0 | F12: 228 | G12: 0 | H12: 46 | I12: 0
A13: 00227 | B13: 0001 | C13: HAROLD ARRIAGA | D13: 1394 | E13: 0 | F13: 1331 | G13: 0 | H13: 2620 | I13: 0
... A21: 00227 | B21: 1905 | C21: RRHH INFRAESTRUCTURA | D21: 1664 | E21: 0 | F21: 368 | G21: 0 | H21: 0 | I21: 0
A22: 10089 | B22: 2021 | C22: LEIDY MOLANO | D22: 114 | E22: 317 | F22: 16 | G22: 85 | H22: 20 | I22: 20
A23: 10089 | B23: 0002 | C23: PISO2 | D23: 0 | E23: 0 | F23: 0 | G23: 0 | H23: 0 | I23: 0
A24: 10089 | B24: 5010 | C24: STEPHANY | D24: 0 | E24: 2 | F24: 0 | G24: 3
A25: 10089 | B25: 0101 | C25: ANA QUINTERO | D25: 0 | E25: 0 | F25: 8 | G25: 1 | H25: 5 | I25: 0
A26: 10089 | B26: 1234 | C26: ALEJANDRO MARQUEZ | D26: 418 | E26: 209 | F26: 295 | G26: 0 | H26: 0 | I26: 0
A27: 10089 | B27: 2020 | C27: ESNEYDER | D27: 0 | E27: 0 | F27: 2 | G27: 0 | H27: 0 | I27: 0
A28: 10089 | B28: 5050 | C28: KTInfraes | D28: 0 | E28: 0 | F28: 0 | G28: 0 | H28: 0 | I28: 0
A29: 10089 | B29: 5060 | C29: NKpromo | D29: 0 | E29: 0 | F29: 0 | G29: 0 | H29: 0 | I29: 0
A30: 10089 | B30: 1107 | C30: CIELO CASTILLO | D30: 345 | E30: 2 | F30: 151 | G30: 33 | H30: 157 | I30: 48
A31: 10089 | B31: 1329 | C31: KELLY GOMEZ | D31: 29 | E31: 21 | F31: 25 | G31: 12 | H31: 6 | I31: 22
A32: 10089 | B32: 1026 | C32: VALERIA HERNANDEZ | D32: 761 | E32: 6 | F32: 1395 | G32: 70 | H32: 108 | I32: 13356
A33: 60686 | B33: 0855 | C33: MAURICIO ROSALES | D33: 0 | E33: 3 | F33: 0 | G33: 0 | H33: 0 | I33: 0
A34: 60686 | B34: 0856 | C34: MILTON | D34: 155 | E34: 0 | F34: 203 | G34: 0 | H34: 5 | I34: 0
A35: 60686 | B35: 1010 | C35: ISABEL HERNANDEZ | D35: 418 | E35: 0 | F35: 269 | G35: 0 | H35: 2129 | I35: 0
A36: 60686 | B36: 1111 | C36: JARDANY VILLANUEVA | D36: 0 | E36: 0 | F36: 0 | G36: 0 | H36: 0 | I36: 0
... A60: 60686 | B60: 9176 | C60: BEATRIZ ROJAS | D60: 3 | E60: 0 | F60: 47 | G60: 0 | H60: 0 | I60: 0
A61: 00084 | B61: 0202 | C61: Harold | D61: 0 | E61: 0 | F61: 0 | G61: 0 | H61: 1149 | I61: 0
A62: 00084 | B62: 0625 | C62: PAOLAH | D62: 0 | E62: 0 | F62: 0 | G62: 0 | H62: 0 | I62: 0
A63: 00084 | B63: 1016 | C63: JOHN EIDER | D63: 0 | E63: 0 | F63: 1647 | G63: 0 | H63: 1856 | I63: 0
A64: 00084 | B64: 1130 | C64: ANDRES VILLARREAL | D64: 0 | E64: 0 | F64: 0 | G64: 0 | H64: 0 | I64: 0
A65: 00084 | B65: 1234 | C65: DANIEL M | D65: 128 | E65: 0 | F65: 131 | G65: 0 | H65: 87 | I65: 0
A66: 00084 | B66: 1973 | C66: LUIS FV | D66: 46 | E66: 0 | F66: 43 | G66: 0 | H66: 50 | I66: 0
A67: 00084 | B67: 2020 | C67: Esneyder | D67: 0 | E67: 0 | F67: 12 | G67: 0 | H67: 22 | I67: 0
A68: 00084 | B68: 2022 | C68: LUZ STELLA VALENCIA | D68: 46 | E68: 0 | F68: 99 | G68: 0 | H68: 142 | I68: 0
A69: 00084 | B69: 2028 | C69: KAROL | D69: 996 | E69: 0 | F69: 976 | G69: 0 | H69: 828 | I69: 0
A70: 00084 | B70: 2029 | C70: SCAN INFRA | D70: 0 | E70: 0 | F70: 0 | G70: 0 | H70: 0 | I70: 0
...

Sheet extras_costos
A1: total_contratado_bn | B1: costo_color | C1: costo_bn | D1: costo_bn_extra
A2: 5000 | B2: 274 | C2: 205000 | D2: 30
A5: IMPRESORA | B5: TIPO | C5: UBICACIÓN | D5: S/N | E5: TTL JUN | F5: EXTRA_JUN | G5: COSTO EXTRA JUN | H5: COSTO COLOR JUN | I5: TTL JUL | J5: EXTRA JUL | K5: COSTO EXTRA JUL | L5: COSTO COLOR JUL | M5: TTL AGO | N5: EXTRA AGO | O5: COSTO EXTRA AGO | P5: COSTO COLOR AGO | Q5: TTL SEP | R5: EXTRA SEP | S5: COSTO EXTRA SEP | T5: COSTO COLOR SEP | U5: TTL OCT | V5: EXTRA OCT | W5: COSTO EXTRA OCT | X5: COSTO COLOR OCT | Y5: TTL NOV | Z5: EXTRA NOV | AA5: COSTO EXTRA NOV | AB5: COSTO COLOR NOV | AC5: TTL DIC | AD5: EXTRA DIC | AE5: COSTO EXTRA DIC | AF5: COSTO COLOR DIC
A6: Ricoh MP | B6: B/N | C6: Piso 1 - OPERACIONES | D6: 00227 | E6: {=IFERROR(INDEX(contadores!$H:$H,MATCH($D6,contadores!$D:$D,0)),"")} -> 8212 | F6: =IF(E6="","",IF($B6="B/N",IF((E6-$A$2)<0,0,E6-$A$2),0)) -> 3212 | G6: =IF(F6="","",IF(F6>0,IF($B6="B/N",(F6*$D$2),F6*$B$2),0)) -> 96360 | H6: =IF(E6="","",IF(B6="Color",E6*$B$2,0)) -> 0 | I6: {=IFERROR(INDEX(contadores!$J:$J,MATCH($D6,contadores!$D:$D,0)),"")} -> 5885 | J6: =IF(I6="","",IF($B6="B/N",IF((I6-$A$2)<0,0,I6-$A$2),0)) -> 885 | K6: =IF(J6="","",IF(J6>0,IF($B6="B/N",(J6*$D$2),J6*$B$2),0)) -> 26550 | L6: =IF(I6="","",IF(B6="Color",I6*$B$2,0)) -> 0 | M6: {=IFERROR(INDEX(contadores!$L:$L,MATCH($D6,contadores!$D:$D,0)),"")} -> 5381 | N6: =IF(M6="","",IF($B6="B/N",IF((M6-$A$2)<0,0,M6-$A$2),0)) -> 381 | O6: =IF(N6="","",IF(N6>0,IF($B6="B/N",(N6*$D$2),N6*$B$2),0)) -> 11430 | P6: =IF(M6="","",IF(B6="Color",M6*$B$2,0)) -> 0 | Q6: {=IFERROR(INDEX(contadores!$N:$N,MATCH($D6,contadores!$D:$D,0)),"")} | R6: =IF(Q6="","",IF($B6="B/N",IF((Q6-$A$2)<0,0,Q6-$A$2),0)) | S6: =IF(R6="","",IF(R6>0,IF($B6="B/N",(R6*$D$2),R6*$B$2),0)) | T6: =IF(Q6="","",IF(B6="Color",Q6*$B$2,0)) | U6: {=IFERROR(INDEX(contadores!$P:$P,MATCH($D6,contadores!$D:$D,0)),"")} | V6: =IF(U6="","",IF($B6="B/N",IF((U6-$A$2)<0,0,U6-$A$2),0)) | W6: =IF(V6="","",IF(V6>0,IF($B6="B/N",(V6*$D$2),V6*$B$2),0)) | X6: =IF(U6="","",IF(B6="Color",U6*$B$2,0)) | Y6: {=IFERROR(INDEX(contadores!$R:$R,MATCH($D6,contadores!$D:$D,0)),"")} | Z6: =IF(Y6="","",IF($B6="B/N",IF((Y6-$A$2)<0,0,Y6-$A$2),0)) | AA6: =IF(Z6="","",IF(Z6>0,IF($B6="B/N",(Z6*$D$2),Z6*$B$2),0)) | AB6: =IF(Y6="","",IF(B6="Color",Y6*$B$2,0)) | AC6: {=IFERROR(INDEX(contadores!$T:$T,MATCH($D6,contadores!$D:$D,0)),"")} | AD6: =IF(AC6="","",IF($B6="B/N",IF((AC6-$A$2)<0,0,AC6-$A$2),0)) | AE6: =IF(AD6="","",IF(AD6>0,IF($B6="B/N",(AD6*$D$2),AD6*$B$2),0)) | AF6: =IF(AC6="","",IF(B6="Color",AC6*$B$2,0))
A7: Kyocera M3655 | B7: B/N | C7: Piso 1 - PSICOLOGIA | D7: 08082 | E7: {=IFERROR(INDEX(contadores!$H:$H,MATCH($D7,contadores!$D:$D,0)),"")} -> 8545 | F7: =IF(E7="","",IF($B7="B/N",IF((E7-$A$2)<0,0,E7-$A$2),0)) -> 3545 | G7: =IF(F7="","",IF(F7>0,IF($B7="B/N",(F7*$D$2),F7*$B$2),0)) -> 106350 | H7: =IF(E7="","",IF(B7="Color",E7*$B$2,0)) -> 0 | I7: {=IFERROR(INDEX(contadores!$J:$J,MATCH($D7,contadores!$D:$D,0)),"")} -> 5895 | J7: =IF(I7="","",IF($B7="B/N",IF((I7-$A$2)<0,0,I7-$A$2),0)) -> 895 | K7: =IF(J7="","",IF(J7>0,IF($B7="B/N",(J7*$D$2),J7*$B$2),0)) -> 26850 | L7: =IF(I7="","",IF(B7="Color",I7*$B$2,0)) -> 0 | M7: {=IFERROR(INDEX(contadores!$L:$L,MATCH($D7,contadores!$D:$D,0)),"")} -> 5747 | N7: =IF(M7="","",IF($B7="B/N",IF((M7-$A$2)<0,0,M7-$A$2),0)) -> 747 | O7: =IF(N7="","",IF(N7>0,IF($B7="B/N",(N7*$D$2),N7*$B$2),0)) -> 22410 | P7: =IF(M7="","",IF(B7="Color",M7*$B$2,0)) -> 0 | Q7: {=IFERROR(INDEX(contadores!$N:$N,MATCH($D7,contadores!$D:$D,0)),"")} | R7: =IF(Q7="","",IF($B7="B/N",IF((Q7-$A$2)<0,0,Q7-$A$2),0)) | S7: =IF(R7="","",IF(R7>0,IF($B7="B/N",(R7*$D$2),R7*$B$2),0)) | T7: =IF(Q7="","",IF(B7="Color",Q7*$B$2,0)) | U7: {=IFERROR(INDEX(contadores!$P:$P,MATCH($D7,contadores!$D:$D,0)),"")} | V7: =IF(U7="","",IF($B7="B/N",IF((U7-$A$2)<0,0,U7-$A$2),0)) | W7: =IF(V7="","",IF(V7>0,IF($B7="B/N",(V7*$D$2),V7*$B$2),0)) | X7: =IF(U7="","",IF(B7="Color",U7*$B$2,0)) | Y7: {=IFERROR(INDEX(contadores!$R:$R,MATCH($D7,contadores!$D:$D,0)),"")} | Z7: =IF(Y7="","",IF($B7="B/N",IF((Y7-$A$2)<0,0,Y7-$A$2),0)) | AA7: =IF(Z7="","",IF(Z7>0,IF($B7="B/N",(Z7*$D$2),Z7*$B$2),0)) | AB7: =IF(Y7="","",IF(B7="Color",Y7*$B$2,0)) | AC7: {=IFERROR(INDEX(contadores!$T:$T,MATCH($D7,contadores!$D:$D,0)),"")} | AD7: =IF(AC7="","",IF($B7="B/N",IF((AC7-$A$2)<0,0,AC7-$A$2),0)) | AE7: =IF(AD7="","",IF(AD7>0,IF($B7="B/N",(AD7*$D$2),AD7*$B$2),0)) | AF7: =IF(AC7="","",IF(B7="Color",AC7*$B$2,0))
A8: Ricoh MP 5054 | B8: B/N | C8: Piso 2 - CONT | D8: 00084 | E8: {=IFERROR(INDEX(contadores!$H:$H,MATCH($D8,contadores!$D:$D,0)),"")} -> 4617 | F8: =IF(E8="","",IF($B8="B/N",IF((E8-$A$2)<0,0,E8-$A$2),0)) -> 0 | G8: =IF(F8="","",IF(F8>0,IF($B8="B/N",(F8*$D$2),F8*$B$2),0)) -> 0 | H8: =IF(E8="","",IF(B8="Color",E8*$B$2,0)) -> 0 | I8: {=IFERROR(INDEX(contadores!$J:$J,MATCH($D8,contadores!$D:$D,0)),"")} -> 6023 | J8: =IF(I8="","",IF($B8="B/N",IF((I8-$A$2)<0,0,I8-$A$2),0)) -> 1023 | K8: =IF(J8="","",IF(J8>0,IF($B8="B/N",(J8*$D$2),J8*$B$2),0)) -> 30690 | L8: =IF(I8="","",IF(B8="Color",I8*$B$2,0)) -> 0 | M8: {=IFERROR(INDEX(contadores!$L:$L,MATCH($D8,contadores!$D:$D,0)),"")} -> 4657 | N8: =IF(M8="","",IF($B8="B/N",IF((M8-$A$2)<0,0,M8-$A$2),0)) -> 0 | O8: =IF(N8="","",IF(N8>0,IF($B8="B/N",(N8*$D$2),N8*$B$2),0)) -> 0 | P8: =IF(M8="","",IF(B8="Color",M8*$B$2,0)) -> 0 | Q8: {=IFERROR(INDEX(contadores!$N:$N,MATCH($D8,contadores!$D:$D,0)),"")} | R8: =IF(Q8="","",IF($B8="B/N",IF((Q8-$A$2)<0,0,Q8-$A$2),0)) | S8: =IF(R8="","",IF(R8>0,IF($B8="B/N",(R8*$D$2),R8*$B$2),0)) | T8: =IF(Q8="","",IF(B8="Color",Q8*$B$2,0)) | U8: {=IFERROR(INDEX(contadores!$P:$P,MATCH($D8,contadores!$D:$D,0)),"")} | V8: =IF(U8="","",IF($B8="B/N",IF((U8-$A$2)<0,0,U8-$A$2),0)) | W8: =IF(V8="","",IF(V8>0,IF($B8="B/N",(V8*$D$2),V8*$B$2),0)) | X8: =IF(U8="","",IF(B8="Color",U8*$B$2,0)) | Y8: {=IFERROR(INDEX(contadores!$R:$R,MATCH($D8,contadores!$D:$D,0)),"")} | Z8: =IF(Y8="","",IF($B8="B/N",IF((Y8-$A$2)<0,0,Y8-$A$2),0)) | AA8: =IF(Z8="","",IF(Z8>0,IF($B8="B/N",(Z8*$D$2),Z8*$B$2),0)) | AB8: =IF(Y8="","",IF(B8="Color",Y8*$B$2,0)) | AC8: {=IFERROR(INDEX(contadores!$T:$T,MATCH($D8,contadores!$D:$D,0)),"")} | AD8: =IF(AC8="","",IF($B8="B/N",IF((AC8-$A$2)<0,0,AC8-$A$2),0)) | AE8: =IF(AD8="","",IF(AD8>0,IF($B8="B/N",(AD8*$D$2),AD8*$B$2),0)) | AF8: =IF(AC8="","",IF(B8="Color",AC8*$B$2,0))
A9: Ricoh MPC 4504 | B9: B/N | C9: Piso 2 - PROYECTOS | D9: 10089 | E9: {=IFERROR(INDEX(contadores!$H:$H,MATCH($D9,contadores!$D:$D,0)),"")} -> 1674 | F9: =IF(E9="","",IF($B9="B/N",IF((E9-$A$2)<0,0,E9-$A$2),0)) -> 0 | G9: =IF(F9="","",IF(F9>0,IF($B9="B/N",(F9*$D$2),F9*$B$2),0)) -> 0 | H9: =IF(E9="","",IF(B9="Color",E9*$B$2,0)) -> 0 | I9: {=IFERROR(INDEX(contadores!$J:$J,MATCH($D9,contadores!$D:$D,0)),"")} -> 1897 | J9: =IF(I9="","",IF($B9="B/N",IF((I9-$A$2)<0,0,I9-$A$2),0)) -> 0 | K9: =IF(J9="","",IF(J9>0,IF($B9="B/N",(J9*$D$2),J9*$B$2),0)) -> 0 | L9: =IF(I9="","",IF(B9="Color",I9*$B$2,0)) -> 0 | M9: {=IFERROR(INDEX(contadores!$L:$L,MATCH($D9,contadores!$D:$D,0)),"")} -> 327 | N9: =IF(M9="","",IF($B9="B/N",IF((M9-$A$2)<0,0,M9-$A$2),0)) -> 0 | O9: =IF(N9="","",IF(N9>0,IF($B9="B/N",(N9*$D$2),N9*$B$2),0)) -> 0 | P9: =IF(M9="","",IF(B9="Color",M9*$B$2,0)) -> 0 | Q9: {=IFERROR(INDEX(contadores!$N:$N,MATCH($D9,contadores!$D:$D,0)),"")} | R9: =IF(Q9="","",IF($B9="B/N",IF((Q9-$A$2)<0,0,Q9-$A$2),0)) | S9: =IF(R9="","",IF(R9>0,IF($B9="B/N",(R9*$D$2),R9*$B$2),0)) | T9: =IF(Q9="","",IF(B9="Color",Q9*$B$2,0)) | U9: {=IFERROR(INDEX(contadores!$P:$P,MATCH($D9,contadores!$D:$D,0)),"")} | V9: =IF(U9="","",IF($B9="B/N",IF((U9-$A$2)<0,0,U9-$A$2),0)) | W9: =IF(V9="","",IF(V9>0,IF($B9="B/N",(V9*$D$2),V9*$B$2),0)) | X9: =IF(U9="","",IF(B9="Color",U9*$B$2,0)) | Y9: {=IFERROR(INDEX(contadores!$R:$R,MATCH($D9,contadores!$D:$D,0)),"")} | Z9: =IF(Y9="","",IF($B9="B/N",IF((Y9-$A$2)<0,0,Y9-$A$2),0)) | AA9: =IF(Z9="","",IF(Z9>0,IF($B9="B/N",(Z9*$D$2),Z9*$B$2),0)) | AB9: =IF(Y9="","",IF(B9="Color",Y9*$B$2,0)) | AC9: {=IFERROR(INDEX(contadores!$T:$T,MATCH($D9,contadores!$D:$D,0)),"")} | AD9: =IF(AC9="","",IF($B9="B/N",IF((AC9-$A$2)<0,0,AC9-$A$2),0)) | AE9: =IF(AD9="","",IF(AD9>0,IF($B9="B/N",(AD9*$D$2),AD9*$B$2),0)) | AF9: =IF(AC9="","",IF(B9="Color",AC9*$B$2,0))
A10: Ricoh MPC 4504 | B10: Color | C10: Piso 2 - PROYECTOS | D10: C-10089 | E10: {=IFERROR(INDEX(contadores!$H:$H,MATCH($D10,contadores!$D:$D,0)),"")} -> 557 | F10: =IF(E10="","",IF($B10="B/N",IF((E10-$A$2)<0,0,E10-$A$2),0)) -> 0 | G10: =IF(F10="","",IF(F10>0,IF($B10="B/N",(F10*$D$2),F10*$B$2),0)) -> 0 | H10: =IF(E10="","",IF(B10="Color",E10*$B$2,0)) -> 152618 | I10: {=IFERROR(INDEX(contadores!$J:$J,MATCH($D10,contadores!$D:$D,0)),"")} -> 201 | J10: =IF(I10="","",IF($B10="B/N",IF((I10-$A$2)<0,0,I10-$A$2),0)) -> 0 | K10: =IF(J10="","",IF(J10>0,IF($B10="B/N",(J10*$D$2),J10*$B$2),0)) -> 0 | L10: =IF(I10="","",IF(B10="Color",I10*$B$2,0)) -> 55074 | M10: {=IFERROR(INDEX(contadores!$L:$L,MATCH($D10,contadores!$D:$D,0)),"")} -> 13446 | N10: =IF(M10="","",IF($B10="B/N",IF((M10-$A$2)<0,0,M10-$A$2),0)) -> 0 | O10: =IF(N10="","",IF(N10>0,IF($B10="B/N",(N10*$D$2),N10*$B$2),0)) -> 0 | P10: =IF(M10="","",IF(B10="Color",M10*$B$2,0)) -> 3684204 | Q10: {=IFERROR(INDEX(contadores!$N:$N,MATCH($D10,contadores!$D:$D,0)),"")} | R10: =IF(Q10="","",IF($B10="B/N",IF((Q10-$A$2)<0,0,Q10-$A$2),0)) | S10: =IF(R10="","",IF(R10>0,IF($B10="B/N",(R10*$D$2),R10*$B$2),0)) | T10: =IF(Q10="","",IF(B10="Color",Q10*$B$2,0)) | U10: {=IFERROR(INDEX(contadores!$P:$P,MATCH($D10,contadores!$D:$D,0)),"")} | V10: =IF(U10="","",IF($B10="B/N",IF((U10-$A$2)<0,0,U10-$A$2),0)) | W10: =IF(V10="","",IF(V10>0,IF($B10="B/N",(V10*$D$2),V10*$B$2),0)) | X10: =IF(U10="","",IF(B10="Color",U10*$B$2,0)) | Y10: {=IFERROR(INDEX(contadores!$R:$R,MATCH($D10,contadores!$D:$D,0)),"")} | Z10: =IF(Y10="","",IF($B10="B/N",IF((Y10-$A$2)<0,0,Y10-$A$2),0)) | AA10: =IF(Z10="","",IF(Z10>0,IF($B10="B/N",(Z10*$D$2),Z10*$B$2),0)) | AB10: =IF(Y10="","",IF(B10="Color",Y10*$B$2,0)) | AC10: {=IFERROR(INDEX(contadores!$T:$T,MATCH($D10,contadores!$D:$D,0)),"")} | AD10: =IF(AC10="","",IF($B10="B/N",IF((AC10-$A$2)<0,0,AC10-$A$2),0)) | AE10: =IF(AD10="","",IF(AD10>0,IF($B10="B/N",(AD10*$D$2),AD10*$B$2),0)) | AF10: =IF(AC10="","",IF(B10="Color",AC10*$B$2,0))
A11: Ricoh MPC 4504 | B11: B/N | C11: Piso 3 - PROMOTORES | D11: 60686 | E11: {=IFERROR(INDEX(contadores!$H:$H,MATCH($D11,contadores!$D:$D,0)),"")} -> 5380 | F11: =IF(E11="","",IF($B11="B/N",IF((E11-$A$2)<0,0,E11-$A$2),0)) -> 380 | G11: =IF(F11="","",IF(F11>0,IF($B11="B/N",(F11*$D$2),F11*$B$2),0)) -> 11400 | H11: =IF(E11="","",IF(B11="Color",E11*$B$2,0)) -> 0 | I11: {=IFERROR(INDEX(contadores!$J:$J,MATCH($D11,contadores!$D:$D,0)),"")} -> 11583 | J11: =IF(I11="","",IF($B11="B/N",IF((I11-$A$2)<0,0,I11-$A$2),0)) -> 6583 | K11: =IF(J11="","",IF(J11>0,IF($B11="B/N",(J11*$D$2),J11*$B$2),0)) -> 197490 | L11: =IF(I11="","",IF(B11="Color",I11*$B$2,0)) -> 0 | M11: {=IFERROR(INDEX(contadores!$L:$L,MATCH($D11,contadores!$D:$D,0)),"")} -> 7295 | N11: =IF(M11="","",IF($B11="B/N",IF((M11-$A$2)<0,0,M11-$A$2),0)) -> 2295 | O11: =IF(N11="","",IF(N11>0,IF($B11="B/N",(N11*$D$2),N11*$B$2),0)) -> 68850 | P11: =IF(M11="","",IF(B11="Color",M11*$B$2,0)) -> 0 | Q11: {=IFERROR(INDEX(contadores!$N:$N,MATCH($D11,contadores!$D:$D,0)),"")} | R11: =IF(Q11="","",IF($B11="B/N",IF((Q11-$A$2)<0,0,Q11-$A$2),0)) | S11: =IF(R11="","",IF(R11>0,IF($B11="B/N",(R11*$D$2),R11*$B$2),0)) | T11: =IF(Q11="","",IF(B11="Color",Q11*$B$2,0)) | U11: {=IFERROR(INDEX(contadores!$P:$P,MATCH($D11,contadores!$D:$D,0)),"")} | V11: =IF(U11="","",IF($B11="B/N",IF((U11-$A$2)<0,0,U11-$A$2),0)) | W11: =IF(V11="","",IF(V11>0,IF($B11="B/N",(V11*$D$2),V11*$B$2),0)) | X11: =IF(U11="","",IF(B11="Color",U11*$B$2,0)) | Y11: {=IFERROR(INDEX(contadores!$R:$R,MATCH($D11,contadores!$D:$D,0)),"")} | Z11: =IF(Y11="","",IF($B11="B/N",IF((Y11-$A$2)<0,0,Y11-$A$2),0)) | AA11: =IF(Z11="","",IF(Z11>0,IF($B11="B/N",(Z11*$D$2),Z11*$B$2),0)) | AB11: =IF(Y11="","",IF(B11="Color",Y11*$B$2,0)) | AC11: {=IFERROR(INDEX(contadores!$T:$T,MATCH($D11,contadores!$D:$D,0)),"")} | AD11: =IF(AC11="","",IF($B11="B/N",IF((AC11-$A$2)<0,0,AC11-$A$2),0)) | AE11: =IF(AD11="","",IF(AD11>0,IF($B11="B/N",(AD11*$D$2),AD11*$B$2),0)) | AF11: =IF(AC11="","",IF(B11="Color",AC11*$B$2,0))
A12: Ricoh MPC 4504 | B12: Color | C12: Piso 3 - PROMOTORES | D12: C-60686 | E12: {=IFERROR(INDEX(contadores!$H:$H,MATCH($D12,contadores!$D:$D,0)),"")} -> 478 | F12: =IF(E12="","",IF($B12="B/N",IF((E12-$A$2)<0,0,E12-$A$2),0)) -> 0 | G12: =IF(F12="","",IF(F12>0,IF($B12="B/N",(F12*$D$2),F12*$B$2),0)) -> 0 | H12: =IF(E12="","",IF(B12="Color",E12*$B$2,0)) -> 130972 | I12: {=IFERROR(INDEX(contadores!$J:$J,MATCH($D12,contadores!$D:$D,0)),"")} -> 4420 | J12: =IF(I12="","",IF($B12="B/N",IF((I12-$A$2)<0,0,I12-$A$2),0)) -> 0 | K12: =IF(J12="","",IF(J12>0,IF($B12="B/N",(J12*$D$2),J12*$B$2),0)) -> 0 | L12: =IF(I12="","",IF(B12="Color",I12*$B$2,0)) -> 1211080 | M12: {=IFERROR(INDEX(contadores!$L:$L,MATCH($D12,contadores!$D:$D,0)),"")} -> 2202 | N12: =IF(M12="","",IF($B12="B/N",IF((M12-$A$2)<0,0,M12-$A$2),0)) -> 0 | O12: =IF(N12="","",IF(N12>0,IF($B12="B/N",(N12*$D$2),N12*$B$2),0)) -> 0 | P12: =IF(M12="","",IF(B12="Color",M12*$B$2,0)) -> 603348 | Q12: {=IFERROR(INDEX(contadores!$N:$N,MATCH($D12,contadores!$D:$D,0)),"")} | R12: =IF(Q12="","",IF($B12="B/N",IF((Q12-$A$2)<0,0,Q12-$A$2),0)) | S12: =IF(R12="","",IF(R12>0,IF($B12="B/N",(R12*$D$2),R12*$B$2),0)) | T12: =IF(Q12="","",IF(B12="Color",Q12*$B$2,0)) | U12: {=IFERROR(INDEX(contadores!$P:$P,MATCH($D12,contadores!$D:$D,0)),"")} | V12: =IF(U12="","",IF($B12="B/N",IF((U12-$A$2)<0,0,U12-$A$2),0)) | W12: =IF(V12="","",IF(V12>0,IF($B12="B/N",(V12*$D$2),V12*$B$2),0)) | X12: =IF(U12="","",IF(B12="Color",U12*$B$2,0)) | Y12: {=IFERROR(INDEX(contadores!$R:$R,MATCH($D12,contadores!$D:$D,0)),"")} | Z12: =IF(Y12="","",IF($B12="B/N",IF((Y12-$A$2)<0,0,Y12-$A$2),0)) | AA12: =IF(Z12="","",IF(Z12>0,IF($B12="B/N",(Z12*$D$2),Z12*$B$2),0)) | AB12: =IF(Y12="","",IF(B12="Color",Y12*$B$2,0)) | AC12: {=IFERROR(INDEX(contadores!$T:$T,MATCH($D12,contadores!$D:$D,0)),"")} | AD12: =IF(AC12="","",IF($B12="B/N",IF((AC12-$A$2)<0,0,AC12-$A$2),0)) | AE12: =IF(AD12="","",IF(AD12>0,IF($B12="B/N",(AD12*$D$2),AD12*$B$2),0)) | AF12: =IF(AC12="","",IF(B12="Color",AC12*$B$2,0))
A13: Ricoh MP 4504 | B13: B/N | C13: Piso 4 - COM | D13: 60310 | E13: {=IFERROR(INDEX(contadores!$H:$H,MATCH($D13,contadores!$D:$D,0)),"")} -> 108 | F13: =IF(E13="","",IF($B13="B/N",IF((E13-$A$2)<0,0,E13-$A$2),0)) -> 0 | G13: =IF(F13="","",IF(F13>0,IF($B13="B/N",(F13*$D$2),F13*$B$2),0)) -> 0 | H13: =IF(E13="","",IF(B13="Color",E13*$B$2,0)) -> 0 | I13: {=IFERROR(INDEX(contadores!$J:$J,MATCH($D13,contadores!$D:$D,0)),"")} -> 1407 | J13: =IF(I13="","",IF($B13="B/N",IF((I13-$A$2)<0,0,I13-$A$2),0)) -> 0 | K13: =IF(J13="","",IF(J13>0,IF($B13="B/N",(J13*$D$2),J13*$B$2),0)) -> 0 | L13: =IF(I13="","",IF(B13="Color",I13*$B$2,0)) -> 0 | M13: {=IFERROR(INDEX(contadores!$L:$L,MATCH($D13,contadores!$D:$D,0)),"")} -> 174 | N13: =IF(M13="","",IF($B13="B/N",IF((M13-$A$2)<0,0,M13-$A$2),0)) -> 0 | O13: =IF(N13="","",IF(N13>0,IF($B13="B/N",(N13*$D$2),N13*$B$2),0)) -> 0 | P13: =IF(M13="","",IF(B13="Color",M13*$B$2,0)) -> 0 | Q13: {=IFERROR(INDEX(contadores!$N:$N,MATCH($D13,contadores!$D:$D,0)),"")} | R13: =IF(Q13="","",IF($B13="B/N",IF((Q13-$A$2)<0,0,Q13-$A$2),0)) | S13: =IF(R13="","",IF(R13>0,IF($B13="B/N",(R13*$D$2),R13*$B$2),0)) | T13: =IF(Q13="","",IF(B13="Color",Q13*$B$2,0)) | U13: {=IFERROR(INDEX(contadores!$P:$P,MATCH($D13,contadores!$D:$D,0)),"")} | V13: =IF(U13="","",IF($B13="B/N",IF((U13-$A$2)<0,0,U13-$A$2),0)) | W13: =IF(V13="","",IF(V13>0,IF($B13="B/N",(V13*$D$2),V13*$B$2),0)) | X13: =IF(U13="","",IF(B13="Color",U13*$B$2,0)) | Y13: {=IFERROR(INDEX(contadores!$R:$R,MATCH($D13,contadores!$D:$D,0)),"")} | Z13: =IF(Y13="","",IF($B13="B/N",IF((Y13-$A$2)<0,0,Y13-$A$2),0)) | AA13: =IF(Z13="","",IF(Z13>0,IF($B13="B/N",(Z13*$D$2),Z13*$B$2),0)) | AB13: =IF(Y13="","",IF(B13="Color",Y13*$B$2,0)) | AC13: {=IFERROR(INDEX(contadores!$T:$T,MATCH($D13,contadores!$D:$D,0)),"")} | AD13: =IF(AC13="","",IF($B13="B/N",IF((AC13-$A$2)<0,0,AC13-$A$2),0)) | AE13: =IF(AD13="","",IF(AD13>0,IF($B13="B/N",(AD13*$D$2),AD13*$B$2),0)) | AF13: =IF(AC13="","",IF(B13="Color",AC13*$B$2,0))
A14: Ricoh MP 4504 | B14: Color | C14: Piso 4 - COM | D14: C-60310 | E14: {=IFERROR(INDEX(contadores!$H:$H,MATCH($D14,contadores!$D:$D,0)),"")} -> 202 | F14: =IF(E14="","",IF($B14="B/N",IF((E14-$A$2)<0,0,E14-$A$2),0)) -> 0 | G14: =IF(F14="","",IF(F14>0,IF($B14="B/N",(F14*$D$2),F14*$B$2),0)) -> 0 | H14: =IF(E14="","",IF(B14="Color",E14*$B$2,0)) -> 55348 | I14: {=IFERROR(INDEX(contadores!$J:$J,MATCH($D14,contadores!$D:$D,0)),"")} -> 1917 | J14: =IF(I14="","",IF($B14="B/N",IF((I14-$A$2)<0,0,I14-$A$2),0)) -> 0 | K14: =IF(J14="","",IF(J14>0,IF($B14="B/N",(J14*$D$2),J14*$B$2),0)) -> 0 | L14: =IF(I14="","",IF(B14="Color",I14*$B$2,0)) -> 525258 | M14: {=IFERROR(INDEX(contadores!$L:$L,MATCH($D14,contadores!$D:$D,0)),"")} -> 8071 | N14: =IF(M14="","",IF($B14="B/N",IF((M14-$A$2)<0,0,M14-$A$2),0)) -> 0 | O14: =IF(N14="","",IF(N14>0,IF($B14="B/N",(N14*$D$2),N14*$B$2),0)) -> 0 | P14: =IF(M14="","",IF(B14="Color",M14*$B$2,0)) -> 2211454 | Q14: {=IFERROR(INDEX(contadores!$N:$N,MATCH($D14,contadores!$D:$D,0)),"")} | R14: =IF(Q14="","",IF($B14="B/N",IF((Q14-$A$2)<0,0,Q14-$A$2),0)) | S14: =IF(R14="","",IF(R14>0,IF($B14="B/N",(R14*$D$2),R14*$B$2),0)) | T14: =IF(Q14="","",IF(B14="Color",Q14*$B$2,0)) | U14: {=IFERROR(INDEX(contadores!$P:$P,MATCH($D14,contadores!$D:$D,0)),"")} | V14: =IF(U14="","",IF($B14="B/N",IF((U14-$A$2)<0,0,U14-$A$2),0)) | W14: =IF(V14="","",IF(V14>0,IF($B14="B/N",(V14*$D$2),V14*$B$2),0)) | X14: =IF(U14="","",IF(B14="Color",U14*$B$2,0)) | Y14: {=IFERROR(INDEX(contadores!$R:$R,MATCH($D14,contadores!$D:$D,0)),"")} | Z14: =IF(Y14="","",IF($B14="B/N",IF((Y14-$A$2)<0,0,Y14-$A$2),0)) | AA14: =IF(Z14="","",IF(Z14>0,IF($B14="B/N",(Z14*$D$2),Z14*$B$2),0)) | AB14: =IF(Y14="","",IF(B14="Color",Y14*$B$2,0)) | AC14: {=IFERROR(INDEX(contadores!$T:$T,MATCH($D14,contadores!$D:$D,0)),"")} | AD14: =IF(AC14="","",IF($B14="B/N",IF((AC14-$A$2)<0,0,AC14-$A$2),0)) | AE14: =IF(AD14="","",IF(AD14>0,IF($B14="B/N",(AD14*$D$2),AD14*$B$2),0)) | AF14: =IF(AC14="","",IF(B14="Color",AC14*$B$2,0))
